#VRML_SIM R2022b utf8

EXTERNPROTO "https://raw.githubusercontent.com/cyberbotics/webots/R2022b/projects/objects/backgrounds/protos/TexturedBackground.proto"
EXTERNPROTO "https://raw.githubusercontent.com/cyberbotics/webots/R2022b/projects/objects/backgrounds/protos/TexturedBackgroundLight.proto"
EXTERNPROTO "https://raw.githubusercontent.com/cyberbotics/webots/R2022b/projects/objects/floors/protos/CircleArena.proto"

WorldInfo {
}
Viewpoint {
  orientation 0.20965671649275008 0.22076019774678468 -0.9525276879546752 1.5678134232311352
  position -0.24502254572756876 1.2452185617395957 0.7986009946440572
}
TexturedBackground {
}
TexturedBackgroundLight {
}
CircleArena {
  radius 0.385
  floorAppearance PBRAppearance {
    baseColor 0 0 0
    roughness 1
    metalness 0
  }
  wallHeight 1e-05
  wallAppearance PBRAppearance {
    roughness 1
    metalness 0
  }
}
Robot {
  translation 0 0 0.07
  rotation 0 1 0 0
  children [
    DistanceSensor {
      translation 0.03 -0.05 -0.05
      rotation 0 1 0 1.57
      name "left line sensor"
      type "infra-red"
    }
    DistanceSensor {
      translation -0.03 -0.05 -0.05
      rotation 0 1 0 1.57
      name "right line sensor"
      type "infra-red"
    }
    DistanceSensor {
      translation -0.05 -0.05 0
      rotation 0 0 1 -2.3562
      name "forward right sensor"
      lookupTable [
        0 800 0
        0.1 750 0
        0.2 700 0
        0.3 650 0
        0.4 600 0
        0.5 550 0
        0.6 0 0
      ]
    }
    DistanceSensor {
      translation 0.05 -0.05 0
      rotation 0 0 1 -0.7854
      name "forward left sensor"
      lookupTable [
        0 800 0
        0.1 750 0
        0.2 700 0
        0.3 650 0
        0.4 600 0
        0.5 550 0
        0.6 0 0
      ]
    }
    DistanceSensor {
      translation 0 -0.05 0
      rotation 0 0 1 -1.57
      name "front sensor"
      lookupTable [
        0 800 0
        0.1 750 0
        0.2 700 0
        0.3 650 0
        0.4 600 0
        0.5 550 0
        0.6 0 0
      ]
    }
    DistanceSensor {
      translation -0.05 0 0
      rotation 0 0 1 3.141592
      name "right sensor"
      lookupTable [
        0 800 0
        0.1 750 0
        0.2 700 0
        0.3 650 0
        0.4 600 0
        0.5 550 0
        0.6 0 0
      ]
    }
    DistanceSensor {
      translation 0.05 0 0
      name "left sensor"
      lookupTable [
        0 800 0
        0.1 750 0
        0.2 700 0
        0.3 650 0
        0.4 600 0
        0.5 550 0
        0.6 0 0
      ]
    }
    HingeJoint {
      jointParameters HingeJointParameters {
        position 7.679762771801518
        anchor 0.05 0.025 -0.03
      }
      device [
        RotationalMotor {
          name "right motor"
          maxVelocity 12
          maxTorque 720
        }
      ]
      endPoint Solid {
        translation 0.05 0.025 -0.03
        rotation -0.5410925142588366 -0.644130196334805 -0.5406617992633994 4.286793317246558
        children [
          DEF wheel Shape {
            appearance PBRAppearance {
              baseColor 1 1 0
              roughness 1
              metalness 0
            }
            geometry Cylinder {
              height 0.05
              radius 0.025
            }
          }
        ]
        name "left wheel"
        boundingObject USE wheel
        physics Physics {
        }
      }
    }
    HingeJoint {
      jointParameters HingeJointParameters {
        position 30.719056119620795
        anchor -0.05 0.025 -0.03
      }
      device [
        RotationalMotor {
          name "left motor"
          maxVelocity 12
          maxTorque 720
        }
      ]
      endPoint Solid {
        translation -0.05 0.025 -0.03
        rotation 0.3233438885726643 -0.8894176976481603 0.3230865036378866 4.596258913499741
        children [
          DEF wheel Shape {
            appearance PBRAppearance {
              baseColor 1 1 0
              roughness 1
              metalness 0
            }
            geometry Cylinder {
              height 0.05
              radius 0.025
            }
          }
        ]
        name "right wheel"
        boundingObject USE wheel
        physics Physics {
        }
      }
    }
    DEF body Transform {
      children [
        Shape {
          appearance PBRAppearance {
            baseColor 0 0 0
          }
          geometry Box {
            size 0.1 0.1 0.1
          }
        }
      ]
    }
  ]
  boundingObject USE body
  physics Physics {
  }
  controller "mini_sumo_robo_generico"
}
Solid {
  translation 0.28 -0.16 0.14
  children [
    Shape {
      geometry Box {
        size 0.1 0.1 0.1
      }
    }
  ]
  boundingObject Box {
    size 0.1 0.1 0.1
  }
  physics Physics {
  }
}
